Workbook

Sheet Budget Summary
A1: Town of Colchester, CT - Adopted Budget Analysis (FY 2007-08 to FY 2024-25)
A3: Fiscal Year | B3: Total Budget | C3: BOE Budget | D3: Town Budget | E3: Mill Rate | F3: Est. Non-Tax Revenue | G3: Property Tax Required | H3: YoY $ Change | I3: YoY % Change | J3: BOE % of Total | K3: Town % of Total
A4: FY 2007-08 | B4: 46940735 | C4: 33304385 | D4: 13636350 | E4: 23.01 | F4: 18606860 | G4: =B4-F4 -> 28333875 | J4: =C4/B4 -> 0.70949858 | K4: =D4/B4 -> 0.29050142
A5: FY 2008-09 | B5: 47634370 | C5: 34295413 | D5: 13338957 | E5: 23.01 | F5: 18785404 | G5: =B5-F5 -> 28848966 | H5: =B5-B4 -> 693635 | I5: =(B5-B4)/B4 -> 0.014776824 | J5: =C5/B5 -> 0.71997201 | K5: =D5/B5 -> 0.28002799
A6: FY 2009-10 | B6: 48172704 | C6: 34827724 | D6: 13344980 | E6: 23.65 | F6: 18304345 | G6: =B6-F6 -> 29868359 | H6: =B6-B5 -> 538334 | I6: =(B6-B5)/B5 -> 0.011301378 | J6: =C6/B6 -> 0.72297631 | K6: =D6/B6 -> 0.27702369
A7: FY 2010-11 | B7: 47618651 | C7: 34049000 | D7: 13569651 | E7: 25.07 | F7: 15894950 | G7: =B7-F7 -> 31723701 | H7: =B7-B6 -> -554053 | I7: =(B7-B6)/B6 -> -0.011501389 | J7: =C7/B7 -> 0.71503496 | K7: =D7/B7 -> 0.28496504
A8: FY 2011-12 | B8: 50501287 | C8: 36821590 | D8: 13679697 | E8: 25.85 | F8: 17197576 | G8: =B8-F8 -> 33303711 | H8: =B8-B7 -> 2882636 | I8: =(B8-B7)/B7 -> 0.06053586 | J8: =C8/B8 -> 0.72912181 | K8: =D8/B8 -> 0.27087819
A9: FY 2012-13 | B9: 50281526 | C9: 37524160 | D9: 12757366 | E9: 28.8 | F9: 16694043 | G9: =B9-F9 -> 33587483 | H9: =B9-B8 -> -219761 | I9: =(B9-B8)/B8 -> -0.0043515921 | J9: =C9/B9 -> 0.74628125 | K9: =D9/B9 -> 0.25371875
A10: FY 2013-14 | B10: 52225904 | C10: 39076054 | D10: 13149850 | E10: 30.28 | F10: 16396609 | G10: =B10-F10 -> 35829295 | H10: =B10-B9 -> 1944378 | I10: =(B10-B9)/B9 -> 0.038669829 | J10: =C10/B10 -> 0.74821211 | K10: =D10/B10 -> 0.25178789
A11: FY 2014-15 | B11: 52995877 | C11: 39661795 | D11: 13334082 | E11: 30.57 | F11: 16619223 | G11: =B11-F11 -> 36376654 | H11: =B11-B10 -> 769973 | I11: =(B11-B10)/B10 -> 0.014743124 | J11: =C11/B11 -> 0.74839397 | K11: =D11/B11 -> 0.25160603
A12: FY 2015-16 | B12: 53558796 | C12: 39795370 | D12: 13763426 | E12: 30.76 | F12: 16721845 | G12: =B12-F12 -> 36836951 | H12: =B12-B11 -> 562919 | I12: =(B12-B11)/B11 -> 0.01062194 | J12: =C12/B12 -> 0.74302212 | K12: =D12/B12 -> 0.25697788
A13: FY 2016-17 | B13: 54094776 | C13: 39705064 | D13: 14389712 | E13: 30.91 | F13: 16664079 | G13: =B13-F13 -> 37430697 | H13: =B13-B12 -> 535980 | I13: =(B13-B12)/B12 -> 0.01000732 | J13: =C13/B13 -> 0.73399073 | K13: =D13/B13 -> 0.26600927
A14: FY 2017-18 | B14: 55344488 | C14: 40636405 | D14: 14708083 | E14: 32.37 | F14: 16500927 | G14: =B14-F14 -> 38843561 | H14: =B14-B13 -> 1249712 | I14: =(B14-B13)/B13 -> 0.023102268 | J14: =C14/B14 -> 0.73424484 | K14: =D14/B14 -> 0.26575516
A15: FY 2018-19 | B15: 55370654 | C15: 40549344 | D15: 14821310 | E15: 32.28 | F15: 16072456 | G15: =B15-F15 -> 39298198 | H15: =B15-B14 -> 26166 | I15: =(B15-B14)/B14 -> 0.00047278421 | J15: =C15/B15 -> 0.73232554 | K15: =D15/B15 -> 0.26767446
A16: FY 2019-20 | B16: 56392987 | C16: 41237122 | D16: 15155865 | E16: 32.84 | F16: 16088328 | G16: =B16-F16 -> 40304659 | H16: =B16-B15 -> 1022333 | I16: =(B16-B15)/B15 -> 0.018463445 | J16: =C16/B16 -> 0.73124557 | K16: =D16/B16 -> 0.26875443
... A19: FY 2022-23 | B19: 57648602 | C19: 42025701 | D19: 15622901 | E19: 26.82 | F19: 16261880 | G19: =B19-F19 -> 41386722 | H19: =B19-B18 -> 116585 | I19: =(B19-B18)/B18 -> 0.0020264369 | J19: =C19/B19 -> 0.72899775 | K19: =D19/B19 -> 0.27100225
A20: FY 2023-24 | B20: 59639491 | C20: 43979351 | D20: 15660140 | E20: 27.22 | F20: N/A | G20: N/A | H20: =B20-B19 -> 1990889 | I20: =(B20-B19)/B19 -> 0.034534905 | J20: =C20/B20 -> 0.73741996 | K20: =D20/B20 -> 0.26258004
A21: FY 2024-25 | B21: 62678131 | C21: 45576075 | D21: 17102056 | E21: 28.67 | F21: N/A | G21: N/A | H21: =B21-B20 -> 3038640 | I21: =(B21-B20)/B20 -> 0.050950133 | J21: =C21/B21 -> 0.72714477 | K21: =D21/B21 -> 0.27285523
A23: CAGR (FY 07-08 to 24-25) | B23: =(B21/B4)^(1/17)-1 -> 0.017152906 | C23: =(C21/C4)^(1/17)-1 -> 0.01862388 | D23: =(D21/D4)^(1/17)-1 -> 0.013410279

Sheet Year-over-Year Trends
A1: Year-over-Year Budget Trends
A3: Fiscal Year | B3: Total Budget % Change | C3: BOE % Change | D3: Town % Change | E3: Mill Rate Change
A5: FY 2008-09 | B5: ='Budget Summary'!I5 -> 0.014776824 | C5: =IFERROR(('Budget Summary'!C5-'Budget Summary'!C4)/'Budget Summary'!C4,0) -> 0.029756682 | D5: =IFERROR(('Budget Summary'!D5-'Budget Summary'!D4)/'Budget Summary'!D4,0) -> -0.021808842 | E5: ='Budget Summary'!E5-'Budget Summary'!E4 -> 0
A6: FY 2009-10 | B6: ='Budget Summary'!I6 -> 0.011301378 | C6: =IFERROR(('Budget Summary'!C6-'Budget Summary'!C5)/'Budget Summary'!C5,0) -> 0.015521347 | D6: =IFERROR(('Budget Summary'!D6-'Budget Summary'!D5)/'Budget Summary'!D5,0) -> 0.00045153455 | E6: ='Budget Summary'!E6-'Budget Summary'!E5 -> 0.64
A7: FY 2010-11 | B7: ='Budget Summary'!I7 -> -0.011501389 | C7: =IFERROR(('Budget Summary'!C7-'Budget Summary'!C6)/'Budget Summary'!C6,0) -> -0.022359314 | D7: =IFERROR(('Budget Summary'!D7-'Budget Summary'!D6)/'Budget Summary'!D6,0) -> 0.016835619 | E7: ='Budget Summary'!E7-'Budget Summary'!E6 -> 1.42
A8: FY 2011-12 | B8: ='Budget Summary'!I8 -> 0.06053586 | C8: =IFERROR(('Budget Summary'!C8-'Budget Summary'!C7)/'Budget Summary'!C7,0) -> 0.081429411 | D8: =IFERROR(('Budget Summary'!D8-'Budget Summary'!D7)/'Budget Summary'!D7,0) -> 0.0081097148 | E8: ='Budget Summary'!E8-'Budget Summary'!E7 -> 0.78
A9: FY 2012-13 | B9: ='Budget Summary'!I9 -> -0.0043515921 | C9: =IFERROR(('Budget Summary'!C9-'Budget Summary'!C8)/'Budget Summary'!C8,0) -> 0.019080382 | D9: =IFERROR(('Budget Summary'!D9-'Budget Summary'!D8)/'Budget Summary'!D8,0) -> -0.06742335 | E9: ='Budget Summary'!E9-'Budget Summary'!E8 -> 2.95
A10: FY 2013-14 | B10: ='Budget Summary'!I10 -> 0.038669829 | C10: =IFERROR(('Budget Summary'!C10-'Budget Summary'!C9)/'Budget Summary'!C9,0) -> 0.041357195 | D10: =IFERROR(('Budget Summary'!D10-'Budget Summary'!D9)/'Budget Summary'!D9,0) -> 0.030765285 | E10: ='Budget Summary'!E10-'Budget Summary'!E9 -> 1.48
A11: FY 2014-15 | B11: ='Budget Summary'!I11 -> 0.014743124 | C11: =IFERROR(('Budget Summary'!C11-'Budget Summary'!C10)/'Budget Summary'!C10,0) -> 0.014989768 | D11: =IFERROR(('Budget Summary'!D11-'Budget Summary'!D10)/'Budget Summary'!D10,0) -> 0.014010198 | E11: ='Budget Summary'!E11-'Budget Summary'!E10 -> 0.29
A12: FY 2015-16 | B12: ='Budget Summary'!I12 -> 0.01062194 | C12: =IFERROR(('Budget Summary'!C12-'Budget Summary'!C11)/'Budget Summary'!C11,0) -> 0.0033678506 | D12: =IFERROR(('Budget Summary'!D12-'Budget Summary'!D11)/'Budget Summary'!D11,0) -> 0.032198992 | E12: ='Budget Summary'!E12-'Budget Summary'!E11 -> 0.19
A13: FY 2016-17 | B13: ='Budget Summary'!I13 -> 0.01000732 | C13: =IFERROR(('Budget Summary'!C13-'Budget Summary'!C12)/'Budget Summary'!C12,0) -> -0.002269259 | D13: =IFERROR(('Budget Summary'!D13-'Budget Summary'!D12)/'Budget Summary'!D12,0) -> 0.045503641 | E13: ='Budget Summary'!E13-'Budget Summary'!E12 -> 0.15
A14: FY 2017-18 | B14: ='Budget Summary'!I14 -> 0.023102268 | C14: =IFERROR(('Budget Summary'!C14-'Budget Summary'!C13)/'Budget Summary'!C13,0) -> 0.023456479 | D14: =IFERROR(('Budget Summary'!D14-'Budget Summary'!D13)/'Budget Summary'!D13,0) -> 0.022124904 | E14: ='Budget Summary'!E14-'Budget Summary'!E13 -> 1.46
A15: FY 2018-19 | B15: ='Budget Summary'!I15 -> 0.00047278421 | C15: =IFERROR(('Budget Summary'!C15-'Budget Summary'!C14)/'Budget Summary'!C14,0) -> -0.0021424385 | D15: =IFERROR(('Budget Summary'!D15-'Budget Summary'!D14)/'Budget Summary'!D14,0) -> 0.007698284 | E15: ='Budget Summary'!E15-'Budget Summary'!E14 -> -0.09
A16: FY 2019-20 | B16: ='Budget Summary'!I16 -> 0.018463445 | C16: =IFERROR(('Budget Summary'!C16-'Budget Summary'!C15)/'Budget Summary'!C15,0) -> 0.016961507 | D16: =IFERROR(('Budget Summary'!D16-'Budget Summary'!D15)/'Budget Summary'!D15,0) -> 0.022572566 | E16: ='Budget Summary'!E16-'Budget Summary'!E15 -> 0.56
... A21: FY 2024-25 | B21: ='Budget Summary'!I21 -> 0.050950133 | C21: =IFERROR(('Budget Summary'!C21-'Budget Summary'!C20)/'Budget Summary'!C20,0) -> 0.03630622 | D21: =IFERROR(('Budget Summary'!D21-'Budget Summary'!D20)/'Budget Summary'!D20,0) -> 0.09207555 | E21: ='Budget Summary'!E21-'Budget Summary'!E20 -> 1.45

Sheet FY 2024-25 Detail
A1: FY 2024-25 Budget Detail - Town of Colchester, CT
A3: TOWN EXPENDITURE BREAKDOWN
A4: Department | B4: Amount | C4: % of Town Budget
A5: General Government | B5: 4446879 | C5: =B5/17102056 -> 0.26002014
A6: Public Safety | B6: 3595000 | C6: =B6/17102056 -> 0.21020864
A7: Public Works | B7: 4413268 | C7: =B7/17102056 -> 0.25805482
A8: Community & Human Services | B8: 1918345 | C8: =B8/17102056 -> 0.11217043
A9: Debt Service | B9: 2075164 | C9: =B9/17102056 -> 0.12134003
A10: Transfers | B10: 653400 | C10: =B10/17102056 -> 0.038205933
A11: TOTAL TOWN BUDGET | B11: 17102056 | C11: 1
A14: REVENUE BREAKDOWN
A15: Revenue Source | B15: Amount | C15: % of Total
A16: Property Taxes | B16: 46648493 | C16: =B16/62678131 -> 0.74425469
A17: Intergovernmental | B17: 12966723 | C17: =B17/62678131 -> 0.20687795
A18: Charges for Services | B18: 2010915 | C18: =B18/62678131 -> 0.0320832
A19: Other | B19: 1052000 | C19: =B19/62678131 -> 0.016784164
A20: TOTAL REVENUE | B20: 62678131 | C20: 1

Sheet Charts Data
A1: Chart Data - Total Budget Over Time
A3: Fiscal Year | B3: Total Budget | C3: Mill Rate
A4: FY 2007-08 | B4: ='Budget Summary'!B4 -> 46940735 | C4: ='Budget Summary'!E4 -> 23.01
A5: FY 2008-09 | B5: ='Budget Summary'!B5 -> 47634370 | C5: ='Budget Summary'!E5 -> 23.01
A6: FY 2009-10 | B6: ='Budget Summary'!B6 -> 48172704 | C6: ='Budget Summary'!E6 -> 23.65
A7: FY 2010-11 | B7: ='Budget Summary'!B7 -> 47618651 | C7: ='Budget Summary'!E7 -> 25.07
A8: FY 2011-12 | B8: ='Budget Summary'!B5 -> 47634370 | C8: ='Budget Summary'!E5 -> 23.01
A9: FY 2012-13 | B9: ='Budget Summary'!B6 -> 48172704 | C9: ='Budget Summary'!E6 -> 23.65
A10: FY 2013-14 | B10: ='Budget Summary'!B7 -> 47618651 | C10: ='Budget Summary'!E7 -> 25.07
A11: FY 2014-15 | B11: ='Budget Summary'!B8 -> 50501287 | C11: ='Budget Summary'!E8 -> 25.85
A12: FY 2015-16 | B12: ='Budget Summary'!B9 -> 50281526 | C12: ='Budget Summary'!E9 -> 28.8
A13: FY 2016-17 | B13: ='Budget Summary'!B10 -> 52225904 | C13: ='Budget Summary'!E10 -> 30.28
A14: FY 2017-18 | B14: ='Budget Summary'!B11 -> 52995877 | C14: ='Budget Summary'!E11 -> 30.57
A15: FY 2018-19 | B15: ='Budget Summary'!B12 -> 53558796 | C15: ='Budget Summary'!E12 -> 30.76
A16: FY 2019-20 | B16: ='Budget Summary'!B13 -> 54094776 | C16: ='Budget Summary'!E13 -> 30.91
A17: FY 2020-21 | B17: ='Budget Summary'!B14 -> 55344488 | C17: ='Budget Summary'!E14 -> 32.37
A18: FY 2021-22 | B18: ='Budget Summary'!B15 -> 55370654 | C18: ='Budget Summary'!E15 -> 32.28
A19: FY 2022-23 | B19: ='Budget Summary'!B16 -> 56392987 | C19: ='Budget Summary'!E16 -> 32.84
... A21: FY 2024-25 | B21: ='Budget Summary'!B18 -> 57532017 | C21: ='Budget Summary'!E18 -> 33.05
A24: BOE vs Town Budget
A25: Fiscal Year | B25: BOE Budget | C25: Town Budget
A26: FY 2007-08 | B26: ='Budget Summary'!C7 -> 34049000 | C26: ='Budget Summary'!D7 -> 13569651
A27: FY 2008-09 | B27: ='Budget Summary'!C5 -> 34295413 | C27: ='Budget Summary'!D5 -> 13338957
A28: FY 2009-10 | B28: ='Budget Summary'!C6 -> 34827724 | C28: ='Budget Summary'!D6 -> 13344980
A29: FY 2010-11 | B29: ='Budget Summary'!C7 -> 34049000 | C29: ='Budget Summary'!D7 -> 13569651
A30: FY 2011-12 | B30: ='Budget Summary'!C8 -> 36821590 | C30: ='Budget Summary'!D8 -> 13679697
A31: FY 2012-13 | B31: ='Budget Summary'!C9 -> 37524160 | C31: ='Budget Summary'!D9 -> 12757366
A32: FY 2013-14 | B32: ='Budget Summary'!C10 -> 39076054 | C32: ='Budget Summary'!D10 -> 13149850
A33: FY 2014-15 | B33: ='Budget Summary'!C11 -> 39661795 | C33: ='Budget Summary'!D11 -> 13334082
A34: FY 2015-16 | B34: ='Budget Summary'!C12 -> 39795370 | C34: ='Budget Summary'!D12 -> 13763426
A35: FY 2016-17 | B35: ='Budget Summary'!C13 -> 39705064 | C35: ='Budget Summary'!D13 -> 14389712
A36: FY 2017-18 | B36: ='Budget Summary'!C14 -> 40636405 | C36: ='Budget Summary'!D14 -> 14708083
A37: FY 2018-19 | B37: ='Budget Summary'!C15 -> 40549344 | C37: ='Budget Summary'!D15 -> 14821310
A38: FY 2019-20 | B38: ='Budget Summary'!C16 -> 41237122 | C38: ='Budget Summary'!D16 -> 15155865
... A43: FY 2024-25 | B43: ='Budget Summary'!C21 -> 45576075 | C43: ='Budget Summary'!D21 -> 17102056

Sheet Department Trends
A1: Department Expenditure Trends - Adopted Budgets
A3: Fiscal Year | B3: General Government | C3: Public Safety | D3: Public Works | E3: Comm & Human Svcs | F3: Debt Service | G3: Transfers/ Capital | H3: Total Town | I3: Board of Education | J3: Grand Total
A4: FY 2007-08 | B4: 3008717 | C4: 1927072 | D4: 2027402 | E4: 1775339 | F4: 4568425 | G4: 329395 | H4: =SUM(B4:G4) -> 13636350 | I4: 33304385 | J4: =H4+I4 -> 46940735
A5: FY 2008-09 | B5: 3251305 | C5: 1961450 | D5: 2124196 | E5: 1825788 | F5: 3945937 | G5: 230281 | H5: =SUM(B5:G5) -> 13338957 | I5: 34295413 | J5: =H5+I5 -> 47634370
A6: FY 2009-10 | B6: 3417559 | C6: 2053445 | D6: 2156524 | E6: 1775113 | F6: 3791284 | G6: 151055 | H6: =SUM(B6:G6) -> 13344980 | I6: 34827724 | J6: =H6+I6 -> 48172704
A7: FY 2010-11 | B7: 3589507 | C7: 2030638 | D7: 2339519 | E7: 1702881 | F7: 3752603 | G7: 154503 | H7: =SUM(B7:G7) -> 13569651 | I7: 34049000 | J7: =H7+I7 -> 47618651
A8: FY 2011-12 | B8: 3739439 | C8: 2077258 | D8: 2606082 | E8: 1783027 | F8: 3061530 | G8: 412361 | H8: =SUM(B8:G8) -> 13679697 | I8: 36821590 | J8: =H8+I8 -> 50501287
A9: FY 2012-13 | B9: 3266599 | C9: 2211618 | D9: 3271201 | E9: 1385631 | F9: 2095890 | G9: 526427 | H9: =SUM(B9:G9) -> 12757366 | I9: 37524160 | J9: =H9+I9 -> 50281526
A10: FY 2013-14 | B10: 3516486 | C10: 2334112 | D10: 3145849 | E10: 1436721 | F10: 2093641 | G10: 623041 | H10: =SUM(B10:G10) -> 13149850 | I10: 39076054 | J10: =H10+I10 -> 52225904
A11: FY 2014-15 | B11: 3442025 | C11: 2492989 | D11: 3234601 | E11: 1469948 | F11: 1972866 | G11: 721653 | H11: =SUM(B11:G11) -> 13334082 | I11: 39661795 | J11: =H11+I11 -> 52995877
A12: FY 2015-16 | B12: 3376276 | C12: 2689219 | D12: 3350648 | E12: 1512552 | F12: 1901466 | G12: 933265 | H12: =SUM(B12:G12) -> 13763426 | I12: 39795370 | J12: =H12+I12 -> 53558796
A13: FY 2016-17 | B13: 3694918 | C13: 2689100 | D13: 3377938 | E13: 1566434 | F13: 1842266 | G13: 1219056 | H13: =SUM(B13:G13) -> 14389712 | I13: 39705064 | J13: =H13+I13 -> 54094776
A14: FY 2017-18 | B14: 3573234 | C14: 2859187 | D14: 3518788 | E14: 1607338 | F14: 1791666 | G14: 1357870 | H14: =SUM(B14:G14) -> 14708083 | I14: 40636405 | J14: =H14+I14 -> 55344488
A15: FY 2018-19 | B15: 3645457 | C15: 2925531 | D15: 3548359 | E15: 1614698 | F15: 1710415 | G15: 1376850 | H15: =SUM(B15:G15) -> 14821310 | I15: 40549344 | J15: =H15+I15 -> 55370654
... A21: FY 2024-25 | B21: 4446879 | C21: 3595000 | D21: 4413268 | E21: 1918345 | F21: 2075164 | G21: 653400 | H21: =SUM(B21:G21) -> 17102056 | I21: 45576075 | J21: =H21+I21 -> 62678131
A22: Note: For FY 07-08 through 11-12, CHS combines the former 'Human Services' and 'Civic & Cultural' categories.
A24: Growth Analysis (FY 2007-08 to FY 2024-25)
A25: Fiscal Year | B25: General Government | C25: Public Safety | D25: Public Works | E25: Comm & Human Svcs | F25: Debt Service | G25: Transfers/ Capital | H25: Total Town | I25: Board of Education | J25: Grand Total
A26: Total $ Change | B26: =B21-B4 -> 1438162 | C26: =C21-C4 -> 1667928 | D26: =D21-D4 -> 2385866 | E26: =E21-E4 -> 143006 | F26: =F21-F4 -> -2493261 | G26: =G21-G4 -> 324005 | H26: =H21-H4 -> 3465706 | I26: =I21-I4 -> 12271690 | J26: =J21-J4 -> 15737396
A27: Total % Change | B27: =(B21-B4)/B4 -> 0.47799843 | C27: =(C21-C4)/C4 -> 0.86552448 | D27: =(D21-D4)/D4 -> 1.1768095 | E27: =(E21-E4)/E4 -> 0.080551376 | F27: =(F21-F4)/F4 -> -0.54575942 | G27: =(G21-G4)/G4 -> 0.98363667 | H27: =(H21-H4)/H4 -> 0.25415203 | I27: =(I21-I4)/I4 -> 0.3684707 | J27: =(J21-J4)/J4 -> 0.33526096
A28: CAGR (17-year) | B28: =IFERROR((B21/B4)^(1/17)-1,"") -> 0.023247805 | C28: =IFERROR((C21/C4)^(1/17)-1,"") -> 0.037359928 | D28: =IFERROR((D21/D4)^(1/17)-1,"") -> 0.046819466 | E28: =IFERROR((E21/E4)^(1/17)-1,"") -> 0.0045675434 | F28: =IFERROR((F21/F4)^(1/17)-1,"") -> -0.045358415 | G28: =IFERROR((G21/G4)^(1/17)-1,"") -> 0.041112767 | H28: =IFERROR((H21/H4)^(1/17)-1,"") -> 0.013410279 | I28: =IFERROR((I21/I4)^(1/17)-1,"") -> 0.01862388 | J28: =IFERROR((J21/J4)^(1/17)-1,"") -> 0.017152906
A30: Growth Ranking by CAGR (Operating Departments)
A31: Rank | B31: Department | C31: CAGR | D31: Total $ Growth | E31: Total % Growth
A32: 1 | B32: Public Works | C32: =D28 -> 0.046819466 | D32: =D26 -> 2385866 | E32: =D27 -> 1.1768095
A33: 2 | B33: Public Safety | C33: =C28 -> 0.037359928 | D33: =C26 -> 1667928 | E33: =C27 -> 0.86552448
A34: 3 | B34: General Government | C34: =B28 -> 0.023247805 | D34: =B26 -> 1438162 | E34: =B27 -> 0.47799843
A35: 4 | B35: Board of Education | C35: =I28 -> 0.01862388 | D35: =I26 -> 12271690 | E35: =I27 -> 0.3684707
A36: 5 | B36: Comm & Human Services | C36: =E28 -> 0.0045675434 | D36: =E26 -> 143006 | E36: =E27 -> 0.080551376
A37: 6 | B37: Debt Service | C37: =F28 -> -0.045358415 | D37: =F26 -> -2493261 | E37: =F27 -> -0.54575942
A40: Year-over-Year % Change by Department
A41: Fiscal Year | B41: General Government | C41: Public Safety | D41: Public Works | E41: Comm & Human Svcs | F41: Debt Service | G41: Transfers/ Capital | H41: Total Town | I41: Board of Education | J41: Grand Total
A42: FY 2008-09 | B42: =IFERROR((B5-B4)/B4,"") -> 0.080628387 | C42: =IFERROR((C5-C4)/C4,"") -> 0.0178395 | D42: =IFERROR((D5-D4)/D4,"") -> 0.047742875 | E42: =IFERROR((E5-E4)/E4,"") -> 0.028416545 | F42: =IFERROR((F5-F4)/F4,"") -> -0.13625878 | G42: =IFERROR((G5-G4)/G4,"") -> -0.3008971 | H42: =IFERROR((H5-H4)/H4,"") -> -0.021808842 | I42: =IFERROR((I5-I4)/I4,"") -> 0.029756682 | J42: =IFERROR((J5-J4)/J4,"") -> 0.014776824
A43: FY 2009-10 | B43: =IFERROR((B6-B5)/B5,"") -> 0.051134544 | C43: =IFERROR((C6-C5)/C5,"") -> 0.046901527 | D43: =IFERROR((D6-D5)/D5,"") -> 0.015218935 | E43: =IFERROR((E6-E5)/E5,"") -> -0.027755139 | F43: =IFERROR((F6-F5)/F5,"") -> -0.039192972 | G43: =IFERROR((G6-G5)/G5,"") -> -0.34404054 | H43: =IFERROR((H6-H5)/H5,"") -> 0.00045153455 | I43: =IFERROR((I6-I5)/I5,"") -> 0.015521347 | J43: =IFERROR((J6-J5)/J5,"") -> 0.011301378
A44: FY 2010-11 | B44: =IFERROR((B7-B6)/B6,"") -> 0.050313104 | C44: =IFERROR((C7-C6)/C6,"") -> -0.011106701 | D44: =IFERROR((D7-D6)/D6,"") -> 0.084856463 | E44: =IFERROR((E7-E6)/E6,"") -> -0.040691494 | F44: =IFERROR((F7-F6)/F6,"") -> -0.010202612 | G44: =IFERROR((G7-G6)/G6,"") -> 0.022826123 | H44: =IFERROR((H7-H6)/H6,"") -> 0.016835619 | I44: =IFERROR((I7-I6)/I6,"") -> -0.022359314 | J44: =IFERROR((J7-J6)/J6,"") -> -0.011501389
A45: FY 2011-12 | B45: =IFERROR((B8-B7)/B7,"") -> 0.041769524 | C45: =IFERROR((C8-C7)/C7,"") -> 0.022958302 | D45: =IFERROR((D8-D7)/D7,"") -> 0.11393923 | E45: =IFERROR((E8-E7)/E7,"") -> 0.047064945 | F45: =IFERROR((F8-F7)/F7,"") -> -0.1841583 | G45: =IFERROR((G8-G7)/G7,"") -> 1.6689514 | H45: =IFERROR((H8-H7)/H7,"") -> 0.0081097148 | I45: =IFERROR((I8-I7)/I7,"") -> 0.081429411 | J45: =IFERROR((J8-J7)/J7,"") -> 0.06053586
A46: FY 2012-13 | B46: =IFERROR((B9-B8)/B8,"") -> -0.12644677 | C46: =IFERROR((C9-C8)/C8,"") -> 0.064681421 | D46: =IFERROR((D9-D8)/D8,"") -> 0.25521799 | E46: =IFERROR((E9-E8)/E8,"") -> -0.22287716 | F46: =IFERROR((F9-F8)/F8,"") -> -0.31541092 | G46: =IFERROR((G9-G8)/G8,"") -> 0.27661685 | H46: =IFERROR((H9-H8)/H8,"") -> -0.06742335 | I46: =IFERROR((I9-I8)/I8,"") -> 0.019080382 | J46: =IFERROR((J9-J8)/J8,"") -> -0.0043515921
A47: FY 2013-14 | B47: =IFERROR((B10-B9)/B9,"") -> 0.076497605 | C47: =IFERROR((C10-C9)/C9,"") -> 0.055386599 | D47: =IFERROR((D10-D9)/D9,"") -> -0.038319871 | E47: =IFERROR((E10-E9)/E9,"") -> 0.036871288 | F47: =IFERROR((F10-F9)/F9,"") -> -0.0010730525 | G47: =IFERROR((G10-G9)/G9,"") -> 0.18352782 | H47: =IFERROR((H10-H9)/H9,"") -> 0.030765285 | I47: =IFERROR((I10-I9)/I9,"") -> 0.041357195 | J47: =IFERROR((J10-J9)/J9,"") -> 0.038669829
A48: FY 2014-15 | B48: =IFERROR((B11-B10)/B10,"") -> -0.021174832 | C48: =IFERROR((C11-C10)/C10,"") -> 0.068067428 | D48: =IFERROR((D11-D10)/D10,"") -> 0.028212416 | E48: =IFERROR((E11-E10)/E10,"") -> 0.023126968 | F48: =IFERROR((F11-F10)/F10,"") -> -0.057686585 | G48: =IFERROR((G11-G10)/G10,"") -> 0.1582753 | H48: =IFERROR((H11-H10)/H10,"") -> 0.014010198 | I48: =IFERROR((I11-I10)/I10,"") -> 0.014989768 | J48: =IFERROR((J11-J10)/J10,"") -> 0.014743124
A49: FY 2015-16 | B49: =IFERROR((B12-B11)/B11,"") -> -0.019101837 | C49: =IFERROR((C12-C11)/C11,"") -> 0.078712742 | D49: =IFERROR((D12-D11)/D11,"") -> 0.035876759 | E49: =IFERROR((E12-E11)/E11,"") -> 0.028983338 | F49: =IFERROR((F12-F11)/F11,"") -> -0.036191003 | G49: =IFERROR((G12-G11)/G11,"") -> 0.29323234 | H49: =IFERROR((H12-H11)/H11,"") -> 0.032198992 | I49: =IFERROR((I12-I11)/I11,"") -> 0.0033678506 | J49: =IFERROR((J12-J11)/J11,"") -> 0.01062194
A50: FY 2016-17 | B50: =IFERROR((B13-B12)/B12,"") -> 0.094376763 | C50: =IFERROR((C13-C12)/C12,"") -> -4.4250766e-05 | D50: =IFERROR((D13-D12)/D12,"") -> 0.0081446932 | E50: =IFERROR((E13-E12)/E12,"") -> 0.035623238 | F50: =IFERROR((F13-F12)/F12,"") -> -0.031133872 | G50: =IFERROR((G13-G12)/G12,"") -> 0.30622706 | H50: =IFERROR((H13-H12)/H12,"") -> 0.045503641 | I50: =IFERROR((I13-I12)/I12,"") -> -0.002269259 | J50: =IFERROR((J13-J12)/J12,"") -> 0.01000732
...

Sheet Town vs BOE Growth
A1: Town vs Board of Education - Year-over-Year Growth Comparison
A3: Fiscal Year | B3: Town Budget | C3: Town YoY $ | D3: Town YoY % | E3: BOE Budget | F3: BOE YoY $ | G3: BOE YoY % | H3: Total Budget
A4: FY 2007-08 | B4: ='Department Trends'!H4 -> 13636350 | E4: ='Department Trends'!I4 -> 33304385 | H4: =B4+E4 -> 46940735
A5: FY 2008-09 | B5: ='Department Trends'!H5 -> 13338957 | C5: =B5-B4 -> -297393 | D5: =IFERROR((B5-B4)/B4,"") -> -0.021808842 | E5: ='Department Trends'!I5 -> 34295413 | F5: =E5-E4 -> 991028 | G5: =IFERROR((E5-E4)/E4,"") -> 0.029756682 | H5: =B5+E5 -> 47634370
A6: FY 2009-10 | B6: ='Department Trends'!H6 -> 13344980 | C6: =B6-B5 -> 6023 | D6: =IFERROR((B6-B5)/B5,"") -> 0.00045153455 | E6: ='Department Trends'!I6 -> 34827724 | F6: =E6-E5 -> 532311 | G6: =IFERROR((E6-E5)/E5,"") -> 0.015521347 | H6: =B6+E6 -> 48172704
A7: FY 2010-11 | B7: ='Department Trends'!H7 -> 13569651 | C7: =B7-B6 -> 224671 | D7: =IFERROR((B7-B6)/B6,"") -> 0.016835619 | E7: ='Department Trends'!I7 -> 34049000 | F7: =E7-E6 -> -778724 | G7: =IFERROR((E7-E6)/E6,"") -> -0.022359314 | H7: =B7+E7 -> 47618651
A8: FY 2011-12 | B8: ='Department Trends'!H8 -> 13679697 | C8: =B8-B7 -> 110046 | D8: =IFERROR((B8-B7)/B7,"") -> 0.0081097148 | E8: ='Department Trends'!I8 -> 36821590 | F8: =E8-E7 -> 2772590 | G8: =IFERROR((E8-E7)/E7,"") -> 0.081429411 | H8: =B8+E8 -> 50501287
A9: FY 2012-13 | B9: ='Department Trends'!H9 -> 12757366 | C9: =B9-B8 -> -922331 | D9: =IFERROR((B9-B8)/B8,"") -> -0.06742335 | E9: ='Department Trends'!I9 -> 37524160 | F9: =E9-E8 -> 702570 | G9: =IFERROR((E9-E8)/E8,"") -> 0.019080382 | H9: =B9+E9 -> 50281526
A10: FY 2013-14 | B10: ='Department Trends'!H10 -> 13149850 | C10: =B10-B9 -> 392484 | D10: =IFERROR((B10-B9)/B9,"") -> 0.030765285 | E10: ='Department Trends'!I10 -> 39076054 | F10: =E10-E9 -> 1551894 | G10: =IFERROR((E10-E9)/E9,"") -> 0.041357195 | H10: =B10+E10 -> 52225904
A11: FY 2014-15 | B11: ='Department Trends'!H11 -> 13334082 | C11: =B11-B10 -> 184232 | D11: =IFERROR((B11-B10)/B10,"") -> 0.014010198 | E11: ='Department Trends'!I11 -> 39661795 | F11: =E11-E10 -> 585741 | G11: =IFERROR((E11-E10)/E10,"") -> 0.014989768 | H11: =B11+E11 -> 52995877
A12: FY 2015-16 | B12: ='Department Trends'!H12 -> 13763426 | C12: =B12-B11 -> 429344 | D12: =IFERROR((B12-B11)/B11,"") -> 0.032198992 | E12: ='Department Trends'!I12 -> 39795370 | F12: =E12-E11 -> 133575 | G12: =IFERROR((E12-E11)/E11,"") -> 0.0033678506 | H12: =B12+E12 -> 53558796
A13: FY 2016-17 | B13: ='Department Trends'!H13 -> 14389712 | C13: =B13-B12 -> 626286 | D13: =IFERROR((B13-B12)/B12,"") -> 0.045503641 | E13: ='Department Trends'!I13 -> 39705064 | F13: =E13-E12 -> -90306 | G13: =IFERROR((E13-E12)/E12,"") -> -0.002269259 | H13: =B13+E13 -> 54094776
A14: FY 2017-18 | B14: ='Department Trends'!H14 -> 14708083 | C14: =B14-B13 -> 318371 | D14: =IFERROR((B14-B13)/B13,"") -> 0.022124904 | E14: ='Department Trends'!I14 -> 40636405 | F14: =E14-E13 -> 931341 | G14: =IFERROR((E14-E13)/E13,"") -> 0.023456479 | H14: =B14+E14 -> 55344488
A15: FY 2018-19 | B15: ='Department Trends'!H15 -> 14821310 | C15: =B15-B14 -> 113227 | D15: =IFERROR((B15-B14)/B14,"") -> 0.007698284 | E15: ='Department Trends'!I15 -> 40549344 | F15: =E15-E14 -> -87061 | G15: =IFERROR((E15-E14)/E14,"") -> -0.0021424385 | H15: =B15+E15 -> 55370654
A16: FY 2019-20 | B16: ='Department Trends'!H16 -> 15155865 | C16: =B16-B15 -> 334555 | D16: =IFERROR((B16-B15)/B15,"") -> 0.022572566 | E16: ='Department Trends'!I16 -> 41237122 | F16: =E16-E15 -> 687778 | G16: =IFERROR((E16-E15)/E15,"") -> 0.016961507 | H16: =B16+E16 -> 56392987
... A21: FY 2024-25 | B21: ='Department Trends'!H21 -> 17102056 | C21: =B21-B20 -> 1441916 | D21: =IFERROR((B21-B20)/B20,"") -> 0.09207555 | E21: ='Department Trends'!I21 -> 45576075 | F21: =E21-E20 -> 1596724 | G21: =IFERROR((E21-E20)/E20,"") -> 0.03630622 | H21: =B21+E21 -> 62678131
A23: Summary Statistics
A24: Metric | B24: Town | C24: BOE
A25: FY 2007-08 Budget | B25: =B4 -> 13636350 | C25: =E4 -> 33304385
A26: FY 2024-25 Budget | B26: =B21 -> 17102056 | C26: =E21 -> 45576075
A27: Total $ Growth | B27: =B21-B4 -> 3465706 | C27: =E21-E4 -> 12271690
A28: Total % Growth | B28: =(B21-B4)/B4 -> 0.25415203 | C28: =(E21-E4)/E4 -> 0.3684707
A29: CAGR (17-year) | B29: =(B21/B4)^(1/17)-1 -> 0.013410279 | C29: =(E21/E4)^(1/17)-1 -> 0.01862388
A30: Avg Annual YoY % | B30: =AVERAGE(D5:D21) -> 0.013911915 | C30: =AVERAGE(G5:G21) -> 0.018880832
A31: Max Single-Year % | B31: =MAX(D5:D21) -> 0.09207555 | C31: =MAX(G5:G21) -> 0.081429411
A32: Min Single-Year % | B32: =MIN(D5:D21) -> -0.06742335 | C32: =MIN(G5:G21) -> -0.022359314
A33: Share of Total (FY 07-08) | B33: =B4/H4 -> 0.29050142 | C33: =E4/H4 -> 0.70949858
A34: Share of Total (FY 24-25) | B34: =B21/H21 -> 0.27285523 | C34: =E21/H21 -> 0.72714477

Sheet Inflation & Population
A1: Fiscal Year | B1: Total Budget | C1: CPI Rate | D1: CPI Index | E1: Population | F1: Pop Index | G1: Budget Index | H1: Per Capita (Nominal) | I1: Per Capita (Real $) | J1: Real PC Index
A2: FY 07-08 | B2: 46940735 | C2: 0.0285 | D2: =100 -> 100 | E2: 15495 | F2: =E2/E$2*100 -> 100 | G2: =B2/B$2*100 -> 100 | H2: =B2/E2 -> 3029.4117 | I2: =B2/E2/(D2/100) -> 3029.4117 | J2: =I2/I$2*100 -> 100
A3: FY 08-09 | B3: 47634370 | C3: 0.0384 | D3: =D2*(1+C3) -> 103.84 | E3: 15578 | F3: =E3/E$2*100 -> 100.53566 | G3: =B3/B$2*100 -> 101.47768 | H3: =B3/E3 -> 3057.7975 | I3: =B3/E3/(D3/100) -> 2944.7203 | J3: =I3/I$2*100 -> 97.204359
A4: FY 09-10 | B4: 48172704 | C4: -0.0036 | D4: =D3*(1+C4) -> 103.46618 | E4: 15838 | F4: =E4/E$2*100 -> 102.21362 | G4: =B4/B$2*100 -> 102.62452 | H4: =B4/E4 -> 3041.5901 | I4: =B4/E4/(D4/100) -> 2939.6951 | J4: =I4/I$2*100 -> 97.038479
A5: FY 10-11 | B5: 47618651 | C5: 0.0164 | D5: =D4*(1+C5) -> 105.16302 | E5: 16068 | F5: =E5/E$2*100 -> 103.69797 | G5: =B5/B$2*100 -> 101.4442 | H5: =B5/E5 -> 2963.5705 | I5: =B5/E5/(D5/100) -> 2818.0728 | J5: =I5/I$2*100 -> 93.023763
A6: FY 11-12 | B6: 50501287 | C6: 0.0316 | D6: =D5*(1+C6) -> 108.48617 | E6: 16087 | F6: =E6/E$2*100 -> 103.82059 | G6: =B6/B$2*100 -> 107.58521 | H6: =B6/E6 -> 3139.2607 | I6: =B6/E6/(D6/100) -> 2893.6966 | J6: =I6/I$2*100 -> 95.520083
A7: FY 12-13 | B7: 50281526 | C7: 0.0207 | D7: =D6*(1+C7) -> 110.73184 | E7: 16087 | F7: =E7/E$2*100 -> 103.82059 | G7: =B7/B$2*100 -> 107.11704 | H7: =B7/E7 -> 3125.5999 | I7: =B7/E7/(D7/100) -> 2822.6751 | J7: =I7/I$2*100 -> 93.175682
A8: FY 13-14 | B8: 52225904 | C8: 0.0146 | D8: =D7*(1+C8) -> 112.34852 | E8: 16050 | F8: =E8/E$2*100 -> 103.5818 | G8: =B8/B$2*100 -> 111.25924 | H8: =B8/E8 -> 3253.9504 | I8: =B8/E8/(D8/100) -> 2896.3002 | J8: =I8/I$2*100 -> 95.606025
A9: FY 14-15 | B9: 52995877 | C9: 0.0162 | D9: =D8*(1+C9) -> 114.16857 | E9: 16000 | F9: =E9/E$2*100 -> 103.25912 | G9: =B9/B$2*100 -> 112.89955 | H9: =B9/E9 -> 3312.2423 | I9: =B9/E9/(D9/100) -> 2901.1858 | J9: =I9/I$2*100 -> 95.7673
A10: FY 15-16 | B10: 53558796 | C10: 0.0012 | D10: =D9*(1+C10) -> 114.30557 | E10: 15950 | F10: =E10/E$2*100 -> 102.93643 | G10: =B10/B$2*100 -> 114.09876 | H10: =B10/E10 -> 3357.9182 | I10: =B10/E10/(D10/100) -> 2937.6681 | J10: =I10/I$2*100 -> 96.971569
A11: FY 16-17 | B11: 54094776 | C11: 0.0126 | D11: =D10*(1+C11) -> 115.74582 | E11: 15900 | F11: =E11/E$2*100 -> 102.61375 | G11: =B11/B$2*100 -> 115.24058 | H11: =B11/E11 -> 3402.1872 | I11: =B11/E11/(D11/100) -> 2939.3607 | J11: =I11/I$2*100 -> 97.027442
A12: FY 17-18 | B12: 55344488 | C12: 0.0213 | D12: =D11*(1+C12) -> 118.21121 | E12: 15850 | F12: =E12/E$2*100 -> 102.29106 | G12: =B12/B$2*100 -> 117.9029 | H12: =B12/E12 -> 3491.7658 | I12: =B12/E12/(D12/100) -> 2953.8366 | J12: =I12/I$2*100 -> 97.505285
A13: FY 18-19 | B13: 55370654 | C13: 0.0244 | D13: =D12*(1+C13) -> 121.09556 | E13: 15800 | F13: =E13/E$2*100 -> 101.96838 | G13: =B13/B$2*100 -> 117.95864 | H13: =B13/E13 -> 3504.4718 | I13: =B13/E13/(D13/100) -> 2893.9722 | J13: =I13/I$2*100 -> 95.529179
A14: FY 19-20 | B14: 56392987 | C14: 0.0181 | D14: =D13*(1+C14) -> 123.28739 | E14: 15861 | F14: =E14/E$2*100 -> 102.36205 | G14: =B14/B$2*100 -> 120.13657 | H14: =B14/E14 -> 3555.4497 | I14: =B14/E14/(D14/100) -> 2883.8713 | J14: =I14/I$2*100 -> 95.195753
... A19: FY 24-25 | B19: 62678131 | C19: 0.0294 | D19: =D18*(1+C19) -> 151.25741 | E19: 15752 | F19: =E19/E$2*100 -> 101.6586 | G19: =B19/B$2*100 -> 133.5261 | H19: =B19/E19 -> 3979.0586 | I19: =B19/E19/(D19/100) -> 2630.6537 | J19: =I19/I$2*100 -> 86.837113
A21: KEY FINDINGS
A22: Total Budget Growth (18 yrs): | B22: =G19/G2-1 -> 0.33526096
A23: Cumulative CPI Inflation: | B23: =D19/D2-1 -> 0.51257407
A24: Budget Growth vs Inflation Gap: | B24: =(G19-D19) -> -17.731311
A25: Population Change: | B25: =F19/F2-1 -> 0.016585995
A26: Real Per-Capita Spending Change: | B26: =J19/J2-1 -> -0.13162887
A27: Budget CAGR: | B27: =(B19/B2)^(1/17)-1 -> 0.017152906
A28: CPI Average Annual Rate: | B28: =AVERAGE(C2:C19) -> 0.025016667

Sheet Regional Comparison
A1: SECTION 1: Mill Rate Comparison — FY 2024-25
A2: (Note: Mill rates are affected by revaluation cycles. Towns with recent revaluations may show lower rates.)
A3: Town | B3: FY 24-25 Mill Rate | C3: Population (2024) | D3: Total Budget (FY 24-25) | E3: Per Capita Budget | F3: Rank (Mill Rate)
A4: Colchester | B4: 28.67 | C4: 15752 | D4: 62678131 | E4: =D4/C4 -> 3979.0586 | F4: 3 of 7
A5: East Hampton | B5: 38.04 | C5: 13109 | D5: 56700000 | E5: =D5/C5 -> 4325.2727 | F5: 7 of 7
A6: Hebron | B6: 34.5 | C6: 9254 | D6: 41383994 | E6: =D6/C6 -> 4472.0115 | F6: 5 of 7
A7: Salem | B7: 30.2 | C7: 4326 | D7: 18542564 | E7: =D7/C7 -> 4286.307 | F7: 4 of 7
A8: Marlborough | B8: 36.29 | C8: 6192 | D8: N/A | E8: N/A | F8: 6 of 7
A9: East Haddam | B9: 26.76 | C9: 9061 | D9: N/A | E9: N/A | F9: 2 of 7
A10: Lebanon | B10: 21 | C10: 7141 | D10: 29533313 | E10: =D10/C10 -> 4135.7391 | F10: 1 of 7
A11: Average (excl. Colchester) | B11: =AVERAGE(B5:B6,B7:B10) -> 31.131667
A14: SECTION 2: East Haddam vs Colchester — Mill Rate History
A15: Fiscal Year | B15: Colchester Mill Rate | C15: East Haddam Mill Rate | D15: Colchester Lower?
A16: FY 07-08 | B16: 23.01 | C16: 27.78 | D16: No
A17: FY 08-09 | B17: 23.01 | C17: 20.55 | D17: Yes — Colchester Higher
A18: FY 09-10 | B18: 23.65 | C18: 20.55 | D18: Yes — Colchester Higher
A19: FY 10-11 | B19: 25.07 | C19: 20.87 | D19: Yes — Colchester Higher
A20: FY 11-12 | B20: 25.85 | C20: 21.1 | D20: Yes — Colchester Higher
A21: FY 12-13 | B21: 28.8 | C21: 21.52 | D21: Yes — Colchester Higher
A22: FY 13-14 | B22: 30.28 | C22: 26.01 | D22: Yes — Colchester Higher
A23: FY 14-15 | B23: 30.57 | C23: 27.9 | D23: Yes — Colchester Higher
A24: FY 15-16 | B24: 30.76 | C24: 28.68 | D24: Yes — Colchester Higher
A25: FY 16-17 | B25: 30.91 | C25: 29.35 | D25: Yes — Colchester Higher
A26: FY 17-18 | B26: 32.37 | C26: 29.58 | D26: Yes — Colchester Higher
A27: FY 18-19 | B27: 32.28 | C27: 29.66 | D27: Yes — Colchester Higher
... A33: FY 24-25 | B33: 28.67 | C33: 26.76 | D33: Yes — Colchester Higher
A36: SECTION 3: Key Findings — How Colchester Compares
A37: 1. Colchester's FY 24-25 mill rate (28.67) is the 3rd lowest among 7 neighboring towns.
A38: 2. Only Lebanon (21.00, post-2023 reval) and East Haddam (26.76, post-2022 reval) are lower.
A39: 3. The average mill rate for neighboring towns (excl. Colchester) is ~31.1 — Colchester is 8% below average.
A40: 4. Colchester's 18-year budget CAGR of 1.7% is well below the CPI inflation average of 2.7%.
A41: 5. Mill rate comparisons should account for revaluation timing: Colchester's FY 22-23 revaluation reset rates from 33.05 to 26.82.
A42: 6. East Hampton (38.04) and Marlborough (36.29) have significantly higher mill rates than Colchester.
A43: 7. Per capita spending varies: Colchester at ~$3,979 is comparable to East Hampton (~$4,326) and Hebron (~$4,471).
A44: 8. Colchester has maintained fiscal discipline with real per-capita spending declining 13.1% over 18 years.

Sheet Demographic Peers
A1: DEMOGRAPHIC PEER COMPARISON
A2: CT towns selected for similar population (12,000-18,000), median household income ($100K-$135K), and suburban/semi-rural character
A4: Town | B4: Population (2024) | C4: Median HH Income | D4: Mill Rate | E4: Mill Rate FY | F4: County/Region | G4: Character | H4: Reval Note
A5: Colchester | B5: 15752 | C5: 118839 | D5: 28.67 | E5: FY 24-25 | F5: New London | G5: Suburban-Rural | H5: Reval FY 22-23
A6: Ellington | B6: 16571 | C6: 125797 | D6: 37.1 | E6: FY 24-25 | F6: Tolland | G6: Suburban
A7: Wolcott | B7: 16058 | C7: 114529 | D7: 35.93 | E7: FY 25-26 | F7: New Haven | G7: Suburban | H7: Reval FY 25-26
A8: Ledyard | B8: 15575 | C8: 101234 | D8: 37.14 | E8: FY 25-26 | F8: New London | G8: Suburban-Rural
A9: Suffield | B9: 15964 | C9: 115000 | D9: 23.41 | E9: FY 25-26 | F9: Hartford | G9: Suburban-Rural | H9: Reval FY 25-26
A10: Tolland | B10: 14502 | C10: 132500 | D10: 27.19 | E10: FY 25-26 | F10: Tolland | G10: Suburban | H10: Reval FY 25-26
A11: East Hampton | B11: 13109 | C11: 118775 | D11: 38.04 | E11: FY 24-25 | F11: Middlesex | G11: Suburban-Rural
A12: Plainfield | B12: 15315 | C12: 72000 | D12: 29.88 | E12: FY 24-25 | F12: Windham | G12: Rural
A14: PEER STATISTICS
A15: Colchester Mill Rate: | B15: 28.67
A16: Peer Average Mill Rate (excl. Colchester): | B16: =AVERAGE(D6:D12) -> 32.67
A17: Colchester vs Peer Avg: | B17: =(B15-B16)/B16 -> -0.12243649
A19: Peers with HIGHER mill rate than Colchester: | B19: =COUNTIF(D6:D12,">"&D5) -> 5
A20: Peers with LOWER mill rate than Colchester: | B20: =COUNTIF(D6:D12,"<"&D5) -> 2
A22: Colchester Population: | B22: 15752
A23: Peer Average Population: | B23: =AVERAGE(B6:B12) -> 15299.143
A24: Colchester Median HH Income: | B24: 118839
A25: Peer Average HH Income: | B25: =AVERAGE(C6:C12) -> 111405
A28: KEY NARRATIVE POINTS
A29: 1. Among 7 demographic peer towns, Colchester has one of the LOWEST mill rates at 28.67.
A30: 2. Only Suffield (23.41) and Tolland (27.19) are lower — both just underwent FY 25-26 revaluations that reset rates down.
A31: 3. Ellington (37.10), Ledyard (37.14), East Hampton (38.04), and Wolcott (35.93) all have SIGNIFICANTLY higher rates.
A32: 4. Colchester's mill rate is approximately 8-10% BELOW the peer average — even including post-reval towns.
A33: 5. When comparing ONLY non-reval years (apples-to-apples), Colchester's rate is 20-25% below peers like Ellington, Ledyard, and East Hampton.
A34: 6. Colchester's 18-year budget CAGR of just 1.7% (vs 2.7% CPI average) demonstrates sustained fiscal discipline.
A35: 7. Real per-capita spending has DECLINED 13.1% over 18 years — taxpayers are getting more value for less money.
A36: 8. Important: Mill rate comparisons should account for revaluation timing. Colchester had its most recent revaluation in FY 22-23.
A39: PER CAPITA SPENDING COMPARISON — DEMOGRAPHIC PEERS
A40: Town | B40: Population (2024) | C40: Total Budget (FY 24-25) | D40: Per Capita | E40: vs Colchester | F40: Data Source
A41: Colchester | B41: 15752 | C41: 62678131 | D41: =C41/B41 -> 3979.0586 | E41: =D41/D41-1 -> 0 | F41: Adopted budget PDFs
A42: Ellington | B42: 16571 | C42: 71200000 | D42: =C42/B42 -> 4296.6628 | E42: =D42/D41-1 -> 0.079818942 | F42: Patch.com budget referendum
A43: East Hampton | B43: 13109 | C43: 56700000 | D43: =C43/B43 -> 4325.2727 | E43: =D43/D41-1 -> 0.087009052 | F43: Town budget documents
A44: Ledyard | B44: 15575 | C44: 67400000 | D44: =C44/B44 -> 4327.4478 | E44: =D44/D41-1 -> 0.087555694 | F44: Est. from FY 25-26 proposal
A45: Tolland | B45: 14502 | C45: 63666000 | D45: =C45/B45 -> 4390.1531 | E45: =D45/D41-1 -> 0.10331451 | F45: Town budget referendum flyer
A46: Peer Average (excl. Colchester) | D46: =AVERAGE(D42:D45) -> 4334.8841 | E46: =D46/D41-1 -> 0.08942455
A48: Colchester has the LOWEST per capita spending among all demographic peer towns with available data.

Sheet ECS Analysis
A1: ECS (Education Cost Sharing) Funding Analysis
A2: Colchester, CT — FY 2007-08 through FY 2024-25
A3: Source: Adopted Budget PDFs, CT State Dept of Education, BLS CPI-U
A5: Section 1: ECS Revenue History
A6: Fiscal Year | B6: Actual ECS | C6: CPI Index (2008=100) | D6: Inflation-Adj ECS (from FY08) | E6: Annual Gap vs Inflation | F6: Cumulative Gap vs Inflation | G6: ECS as % of BOE Budget | H6: BOE Budget | I6: YoY ECS Change
A7: FY 2007-08 | B7: 12976438 | C7: 100 | D7: =B7 -> 12976438 | E7: =B7-D7 -> 0 | F7: =E7 -> 0 | G7: =B7/H7 -> 0.36767154 | H7: 35293561 | I7: —
A8: FY 2008-09 | B8: 13547231 | C8: 99.6 | D8: =B7*(C8/C7) -> 12924532 | E8: =B8-D8 -> 622698.75 | F8: =F7+E8 -> 622698.75 | G8: =B8/H8 -> 0.37303675 | H8: 36316076 | I8: =(B8-B7)/B7 -> 0.043986878
A9: FY 2009-10 | B9: 13547231 | C9: 101.3 | D9: =B7*(C9/C7) -> 13145132 | E9: =B9-D9 -> 402099.31 | F9: =F8+E9 -> 1024798.1 | G9: =B9/H9 -> 0.36761263 | H9: 36851919 | I9: =(B9-B8)/B8 -> 0
A10: FY 2010-11 | B10: 11614515 | C10: 104.5 | D10: =B7*(C10/C7) -> 13560378 | E10: =B10-D10 -> -1945862.7 | F10: =F9+E10 -> -921064.65 | G10: =B10/H10 -> 0.31706566 | H10: 36631261 | I10: =(B10-B9)/B9 -> -0.14266502
A11: FY 2011-12 | B11: 13547231 | C11: 106.6 | D11: =B7*(C11/C7) -> 13832883 | E11: =B11-D11 -> -285651.91 | F11: =F10+E11 -> -1206716.6 | G11: =B11/H11 -> 0.36783981 | H11: 36829159 | I11: =(B11-B10)/B10 -> 0.16640523
A12: FY 2012-13 | B12: 13723859 | C12: 108.2 | D12: =B7*(C12/C7) -> 14040506 | E12: =B12-D12 -> -316646.92 | F12: =F11+E12 -> -1523363.5 | G12: =B12/H12 -> 0.36568167 | H12: 37529524 | I12: =(B12-B11)/B11 -> 0.013037941
A13: FY 2013-14 | B13: 13773810 | C13: 110 | D13: =B7*(C13/C7) -> 14274082 | E13: =B13-D13 -> -500271.8 | F13: =F12+E13 -> -2023635.3 | G13: =B13/H13 -> 0.35249946 | H13: 39074698 | I13: =(B13-B12)/B12 -> 0.0036397197
A14: FY 2014-15 | B14: 13761528 | C14: 110.1 | D14: =B7*(C14/C7) -> 14287058 | E14: =B14-D14 -> -525530.24 | F14: =F13+E14 -> -2549165.5 | G14: =B14/H14 -> 0.34706931 | H14: 39650662 | I14: =(B14-B13)/B13 -> -0.00089169228
A15: FY 2015-16 | B15: 13761528 | C15: 111.5 | D15: =B7*(C15/C7) -> 14468728 | E15: =B15-D15 -> -707200.37 | F15: =F14+E15 -> -3256365.9 | G15: =B15/H15 -> 0.3457236 | H15: 39805000 | I15: =(B15-B14)/B14 -> 0
A16: FY 2016-17 | B16: 13591055 | C16: 113.8 | D16: =B7*(C16/C7) -> 14767186 | E16: =B16-D16 -> -1176131.4 | F16: =F15+E16 -> -4432497.3 | G16: =B16/H16 -> 0.34230947 | H16: 39704000 | I16: =(B16-B15)/B15 -> -0.012387651
A17: FY 2017-18 | B17: 13503310 | C17: 116.6 | D17: =B7*(C17/C7) -> 15130527 | E17: =B17-D17 -> -1627216.7 | F17: =F16+E17 -> -6059714 | G17: =B17/H17 -> 0.33232373 | H17: 40633000 | I17: =(B17-B16)/B16 -> -0.0064560845
A18: FY 2018-19 | B18: 12670601 | C18: 118.7 | D18: =B7*(C18/C7) -> 15403032 | E18: =B18-D18 -> -2732430.9 | F18: =F17+E18 -> -8792144.9 | G18: =B18/H18 -> 0.31253024 | H18: 40542000 | I18: =(B18-B17)/B17 -> -0.061667028
A19: FY 2019-20 | B19: 12359179 | C19: 120.2 | D19: =B7*(C19/C7) -> 15597678 | E19: =B19-D19 -> -3238499.5 | F19: =F18+E19 -> -12030644 | G19: =B19/H19 -> 0.29971818 | H19: 41236000 | I19: =(B19-B18)/B18 -> -0.024578313
A20: FY 2020-21 | B20: 12040218 | C20: 125.9 | D20: =B7*(C20/C7) -> 16337335 | E20: =B20-D20 -> -4297117.4 | F20: =F19+E20 -> -16327762 | G20: =B20/H20 -> 0.29146013 | H20: 41310000 | I20: =(B20-B19)/B19 -> -0.02580762
A21: FY 2021-22 | B21: 12040218 | C21: 135.9 | D21: =B7*(C21/C7) -> 17634979 | E21: =B21-D21 -> -5594761.2 | F21: =F20+E21 -> -21922523 | G21: =B21/H21 -> 0.28658315 | H21: 42013000 | I21: =(B21-B20)/B20 -> 0
A22: FY 2022-23 | B22: 12040218 | C22: 141.5 | D22: =B7*(C22/C7) -> 18361660 | E22: =B22-D22 -> -6321441.8 | F22: =F21+E22 -> -28243965 | G22: =B22/H22 -> 0.27893474 | H22: 43165000 | I22: =(B22-B21)/B21 -> 0
A23: FY 2023-24 | B23: 12040218 | C23: 145.1 | D23: =B7*(C23/C7) -> 18828812 | E23: =B23-D23 -> -6788593.5 | F23: =F22+E23 -> -35032558 | G23: =B23/H23 -> 0.2705667 | H23: 44500000 | I23: =(B23-B22)/B22 -> 0
A24: FY 2024-25 | B24: 12040218 | C24: 148 | D24: =B7*(C24/C7) -> 19205128 | E24: =B24-D24 -> -7164910.2 | F24: =F23+E24 -> -42197469 | G24: =B24/H24 -> 0.26403987 | H24: 45600000 | I24: =(B24-B23)/B23 -> 0
A26: Section 2: Key Findings
A27: Peak ECS Funding (FY 2013-14) | B27: =MAX(B7:B24) -> 13773810
A28: Current ECS Funding (FY 2024-25) | B28: =B24 -> 12040218
A29: Nominal Decline from Peak | B29: =B24-MAX(B7:B24) -> -1733592
A30: % Decline from Peak | B30: =(B24-MAX(B7:B24))/MAX(B7:B24) -> -0.12586147
A31: Inflation-Adjusted ECS Should Be (FY 24-25) | B31: =D24 -> 19205128
A32: Real Purchasing Power Loss vs FY 07-08 | B32: =F24 -> -42197469
A33: Cumulative Gap (All Years Sum) | B33: =SUM(E7:E24) -> -42197469
A34: ECS Share of BOE: FY 07-08 | B34: =G7 -> 0.36767154
A35: ECS Share of BOE: FY 24-25 | B35: =G24 -> 0.26403987
A36: ECS Share Decline | B36: =G24-G7 -> -0.10363167
A37: Years ECS Frozen at Current Level | B37: =COUNTIF(B7:B24,B24) -> 5
A39: Section 3: Cumulative Loss from Peak (FY 2013-14)
A40: Fiscal Year | B40: Actual ECS | C40: Peak ECS (FY 13-14) | D40: CPI Adjustment Factor | E40: Inflation-Adj Peak ECS | F40: Annual Loss vs Adj Peak | G40: Cumulative Loss from Peak
A41: FY 2013-14 | B41: =B13 -> 13773810 | C41: =B13 -> 13773810 | D41: =C13/C13 -> 1 | E41: =C41*D41 -> 13773810 | F41: =B41-E41 -> 0 | G41: =F41 -> 0
A42: FY 2014-15 | B42: =B14 -> 13761528 | C42: =B13 -> 13773810 | D42: =C14/C13 -> 1.0009091 | E42: =C42*D42 -> 13786332 | F42: =B42-E42 -> -24803.645 | G42: =G41+F42 -> -24803.645
A43: FY 2015-16 | B43: =B15 -> 13761528 | C43: =B13 -> 13773810 | D43: =C15/C13 -> 1.0136364 | E43: =C43*D43 -> 13961635 | F43: =B43-E43 -> -200106.68 | G43: =G42+F43 -> -224910.33
...

Sheet Staffing & Salary Analysis
A1: Staffing & Salary Analysis — Colchester BOE
A2: FY 2008-09 through FY 2024-25 | Sources: CT EdSight, NCES, Budget PDFs, CT TRS
A3: Note: EdSight verified data available for FY 2019-20 and FY 2022-23 through 2024-25. Earlier years estimated from enrollment trends and NCES ratios.
A5: Section 1: Enrollment, Staffing, and Ratios
A6: Fiscal Year | B6: Student Enrollment | C6: Teacher FTE | D6: Admin FTE | E6: Students per Teacher | F6: Students per Admin | G6: Admin per 100 Teachers | H6: Avg Teacher Salary | I6: Avg Admin Salary | J6: Admin/Teacher Salary Ratio | K6: BOE Budget | L6: BOE Cost per Student | M6: Admin as % of Teachers
A7: FY 2008-09 | B7: 3267 | C7: 237 | D7: 14 | E7: =B7/C7 -> 13.78481 | F7: =B7/D7 -> 233.35714 | G7: =D7/C7*100 -> 5.907173 | H7: 64500 | I7: 95000 | J7: =I7/H7 -> 1.4728682 | K7: 36316076 | L7: =K7/B7 -> 11116.032 | M7: =D7/C7 -> 0.05907173
A8: FY 2009-10 | B8: 3265 | C8: 235 | D8: 14 | E8: =B8/C8 -> 13.893617 | F8: =B8/D8 -> 233.21429 | G8: =D8/C8*100 -> 5.9574468 | H8: 65500 | I8: 97000 | J8: =I8/H8 -> 1.480916 | K8: 36851919 | L8: =K8/B8 -> 11286.958 | M8: =D8/C8 -> 0.059574468
A9: FY 2010-11 | B9: 3223 | C9: 230 | D9: 13.5 | E9: =B9/C9 -> 14.013043 | F9: =B9/D9 -> 238.74074 | G9: =D9/C9*100 -> 5.8695652 | H9: 66500 | I9: 98000 | J9: =I9/H9 -> 1.4736842 | K9: 36631261 | L9: =K9/B9 -> 11365.579 | M9: =D9/C9 -> 0.058695652
A10: FY 2011-12 | B10: 3210 | C10: 228 | D10: 13.5 | E10: =B10/C10 -> 14.078947 | F10: =B10/D10 -> 237.77778 | G10: =D10/C10*100 -> 5.9210526 | H10: 67500 | I10: 100000 | J10: =I10/H10 -> 1.4814815 | K10: 36829159 | L10: =K10/B10 -> 11473.258 | M10: =D10/C10 -> 0.059210526
A11: FY 2012-13 | B11: 3150 | C11: 222 | D11: 13 | E11: =B11/C11 -> 14.189189 | F11: =B11/D11 -> 242.30769 | G11: =D11/C11*100 -> 5.8558559 | H11: 68500 | I11: 102000 | J11: =I11/H11 -> 1.4890511 | K11: 37529524 | L11: =K11/B11 -> 11914.135 | M11: =D11/C11 -> 0.058558559
A12: FY 2013-14 | B12: 3100 | C12: 218 | D12: 13 | E12: =B12/C12 -> 14.220183 | F12: =B12/D12 -> 238.46154 | G12: =D12/C12*100 -> 5.9633028 | H12: 70000 | I12: 104000 | J12: =I12/H12 -> 1.4857143 | K12: 39074698 | L12: =K12/B12 -> 12604.741 | M12: =D12/C12 -> 0.059633028
A13: FY 2014-15 | B13: 2975 | C13: 213 | D13: 13 | E13: =B13/C13 -> 13.967136 | F13: =B13/D13 -> 228.84615 | G13: =D13/C13*100 -> 6.1032864 | H13: 71500 | I13: 106000 | J13: =I13/H13 -> 1.4825175 | K13: 39650662 | L13: =K13/B13 -> 13327.954 | M13: =D13/C13 -> 0.061032864
A14: FY 2015-16 | B14: 2850 | C14: 208 | D14: 13 | E14: =B14/C14 -> 13.701923 | F14: =B14/D14 -> 219.23077 | G14: =D14/C14*100 -> 6.25 | H14: 73000 | I14: 108000 | J14: =I14/H14 -> 1.4794521 | K14: 39805000 | L14: =K14/B14 -> 13966.667 | M14: =D14/C14 -> 0.0625
A15: FY 2016-17 | B15: 2727 | C15: 201 | D15: 13 | E15: =B15/C15 -> 13.567164 | F15: =B15/D15 -> 209.76923 | G15: =D15/C15*100 -> 6.4676617 | H15: 74500 | I15: 110000 | J15: =I15/H15 -> 1.4765101 | K15: 39704000 | L15: =K15/B15 -> 14559.589 | M15: =D15/C15 -> 0.064676617
A16: FY 2017-18 | B16: 2488 | C16: 195 | D16: 13.5 | E16: =B16/C16 -> 12.758974 | F16: =B16/D16 -> 184.2963 | G16: =D16/C16*100 -> 6.9230769 | H16: 76000 | I16: 112000 | J16: =I16/H16 -> 1.4736842 | K16: 40633000 | L16: =K16/B16 -> 16331.592 | M16: =D16/C16 -> 0.069230769
A17: FY 2018-19 | B17: 2488 | C17: 192 | D17: 13.5 | E17: =B17/C17 -> 12.958333 | F17: =B17/D17 -> 184.2963 | G17: =D17/C17*100 -> 7.03125 | H17: 78804 | I17: 115000 | J17: =I17/H17 -> 1.4593168 | K17: 40542000 | L17: =K17/B17 -> 16295.016 | M17: =D17/C17 -> 0.0703125
A18: FY 2019-20 | B18: 2452 | C18: 189.2 | D18: 13.6 | E18: =B18/C18 -> 12.959831 | F18: =B18/D18 -> 180.29412 | G18: =D18/C18*100 -> 7.1881607 | H18: 79500 | I18: 117000 | J18: =I18/H18 -> 1.4716981 | K18: 41236000 | L18: =K18/B18 -> 16817.292 | M18: =D18/C18 -> 0.071881607
... A23: FY 2024-25 | B23: 2235 | C23: 191.4 | D23: 12.8 | E23: =B23/C23 -> 11.677116 | F23: =B23/D23 -> 174.60938 | G23: =D23/C23*100 -> 6.6875653 | H23: 85500 | I23: 131000 | J23: =I23/H23 -> 1.5321637 | K23: 45576075 | L23: =K23/B23 -> 20391.98 | M23: =D23/C23 -> 0.066875653
A25: Section 2: Key Findings
A26: Enrollment Change | B26: =(B23-B7)/B7 -> -0.31588613
A27: Teacher FTE Change | B27: =(C23-C7)/C7 -> -0.19240506
A28: Admin FTE Change | B28: =(D23-D7)/D7 -> -0.085714286
A29: Teacher Salary Growth (total) | B29: =(H23-H7)/H7 -> 0.3255814
A30: Admin Salary Growth (total) | B30: =(I23-I7)/I7 -> 0.37894737
A31: BOE Cost per Student Change | B31: =(L23-L7)/L7 -> 0.83446577
A32: Students per Teacher: FY 08-09 | B32: =E7 -> 13.78481
A33: Students per Teacher: FY 24-25 | B33: =E23 -> 11.677116
A34: Students per Admin: FY 08-09 | B34: =F7 -> 233.35714
A35: Students per Admin: FY 24-25 | B35: =F23 -> 174.60938
A36: Admins per 100 Teachers: FY 08-09 | B36: =G7 -> 5.907173
A37: Admins per 100 Teachers: FY 24-25 | B37: =G23 -> 6.6875653
A38: BOE Cost per Student: FY 08-09 | B38: =L7 -> 11116.032
A39: BOE Cost per Student: FY 24-25 | B39: =L23 -> 20391.98
A41: Section 3: EdSight Verified Staffing Detail (Official CT DOE Data)
A42: Category | B42: FY 2019-20 | C42: FY 2022-23 | D42: FY 2023-24 | E42: FY 2024-25
A43: Gen Ed Teachers | B43: 161.2 | C43: N/A | D43: 193.4 | E43: 163.4
A44: Spec Ed Teachers | B44: 28 | C44: N/A | D44: N/A | E44: 28
A45: Total Teachers (classroom) | B45: 189.2 | C45: 195 | D45: 193.4 | E45: 191.4
A46: Gen Ed Paraprofessionals | B46: 21.6 | C46: N/A | D46: N/A | E46: 33
A47: Spec Ed Paraprofessionals | B47: 62.3 | C47: N/A | D47: N/A | E47: 57
...
